<?xml version="1.0"?>
<robot xmlns:xacro="http://www.ros.org/wiki/xacro" name="robot">
  <!-- BASE LINK -->

  <link name="base_link">

  </link>


  <!-- FRAME LINK -->

  <joint name="frame_joint" type="fixed">
    <parent link="base_link" />
    <child link="frame" />
    <origin xyz="0 0 0" />
  </joint>

  <link name="frame">
    <visual>
      <origin xyz="0 0 0" />
      <geometry>
        <box size="0.7 0.44 0.3" />
      </geometry>
      <material name="blue" />
    </visual>
    <collision>
      <origin xyz="0 0 0" />
      <geometry>
        <box size="0.7 0.44 0.3" />
      </geometry>
    </collision>
    <xacro:inertial_box mass="50" x="0.7" y="0.44" z="0.3">
      <origin xyz="0 0 0" rpy="0 0 0"/>
  </xacro:inertial_box>
  </link>


  <joint name="left_front_wheel_joint" type="continuous">
    <mimic joint="left_rear_wheel_joint"/>
    <parent link="base_link" />
    <child link="left_front_wheel" />
    <origin xyz="0.2465 0.305 -0.0767" rpy="-${pi/2} 0 0" />
    <axis xyz="0 0 1" />
  </joint>

  <link name="left_front_wheel">
    <visual>
      <geometry>
        <cylinder radius="0.19" length="0.14" />
      </geometry>
      <material name="gray" />
    </visual>
    <collision>
      <geometry>
        <cylinder radius="0.19" length="0.14" />
      </geometry>
    </collision>
        <xacro:inertial_cylinder mass="3" length="0.14" radius="0.19">
            <origin xyz="0 0 0" rpy="0 0 0"/>
        </xacro:inertial_cylinder>
  </link>

  <joint name="left_rear_wheel_joint" type="continuous">
    <parent link="base_link" />
    <child link="left_rear_wheel" />
    <origin xyz="-0.2465 0.305 -0.0767" rpy="-${pi/2} 0 0" />
    <axis xyz="0 0 1" />
  </joint>

  <link name="left_rear_wheel">
    <visual>
      <geometry>
        <cylinder radius="0.19" length="0.14" />
      </geometry>
      <material name="gray" />
    </visual>
    <collision>
      <geometry>
        <cylinder radius="0.19" length="0.14" />
      </geometry>
    </collision>
    <xacro:inertial_cylinder mass="3" length="0.14" radius="0.19">
      <origin xyz="0 0 0" rpy="0 0 0"/>
  </xacro:inertial_cylinder>
  </link>


  <joint name="right_front_wheel_joint" type="continuous">
    <mimic joint="right_rear_wheel_joint"/>
    <parent link="base_link" />
    <child link="right_front_wheel" />
    <origin xyz="0.2465 -0.305 -0.0767" rpy="${pi/2} 0 0" />
    <axis xyz="0 0 -1" />
  </joint>

  <link name="right_front_wheel">
    <visual>
      <geometry>
        <cylinder radius="0.19" length="0.14" />
      </geometry>
      <material name="gray" />
    </visual>
    <collision>
      <geometry>
        <cylinder radius="0.19" length="0.14" />
      </geometry>
    </collision>
    <xacro:inertial_cylinder mass="3" length="0.14" radius="0.19">
      <origin xyz="0 0 0" rpy="0 0 0"/>
  </xacro:inertial_cylinder>
  </link>


  <joint name="right_rear_wheel_joint" type="continuous">
    <parent link="base_link" />
    <child link="right_rear_wheel" />
    <origin xyz="-0.2465 -0.305 -0.0767" rpy="${pi/2} 0 0" />
    <axis xyz="0 0 -1" />
    <command_interface name="velocity" />
    <state_interface name="velocity" />
  </joint>


  <link name="right_rear_wheel">
    <visual>
      <geometry>
        <cylinder radius="0.19" length="0.14" />
      </geometry>
      <material name="gray" />
    </visual>
    <collision>
      <geometry>
        <cylinder radius="0.19" length="0.14" />
      </geometry>
    </collision>
    <xacro:inertial_cylinder mass="3" length="0.14" radius="0.19">
      <origin xyz="0 0 0" rpy="0 0 0"/>
  </xacro:inertial_cylinder>
  </link>


  <joint name="camera_mount_joint" type="fixed">
    <parent link="base_link" />
    <child link="camera_mount_link" />
    <origin xyz="0.32 0 0.18" />
  </joint>


  <link name="camera_mount_link" />
  <xacro:sensor_d455 parent="camera_mount_link" use_nominal_extrinsics="$(arg use_nominal_extrinsics)">
    <origin xyz="0 0 0" rpy="0 0 0"/>
  </xacro:sensor_d455>

</robot>